<?xml version="1.0" ?>
<!-- =================================================================================== -->
<!-- |    This document was autogenerated by xacro from ./robot_descriptions/urdf/universal_robots/relaxed_ik_ur3e_robotiq_85.xacro | -->
<!-- |    EDITING THIS FILE BY HAND IS NOT RECOMMENDED                                 | -->
<!-- =================================================================================== -->
<robot name="simulated_ur3e_robotiq_85_pluw_workcell" xmlns:xacro="http://ros.org/wiki/xacro">
  <!-- THE ROBOT -->
  <gazebo>
    <plugin filename="libgazebo_ros_control.so" name="ros_control">
      <!--robotNamespace>/</robotNamespace-->
      <!--robotSimType>gazebo_ros_control/DefaultRobotHWSim</robotSimType-->
    </plugin>
    <!--
    <plugin name="simulated_gazebo_ros_power_monitor_controller" filename="libgazebo_ros_power_monitor.so">
      <alwaysOn>true</alwaysOn>
      <updateRate>1.0</updateRate>
      <timeout>5</timeout>
      <powerStateTopic>power_state</powerStateTopic>
      <powerStateRate>10.0</powerStateRate>
      <fullChargeCapacity>87.78</fullChargeCapacity>
      <dischargeRate>-474</dischargeRate>
      <chargeRate>525</chargeRate>
      <dischargeVoltage>15.52</dischargeVoltage>
      <chargeVoltage>16.41</chargeVoltage>
    </plugin>
-->
  </gazebo>
  <!--
  Author: Felix Messmer
-->

  <link name="world" />
  <link name="app" />
  <joint name="world_app_joint" type="fixed">
    <parent link="world"/>
    <child link="app"/>
    <origin xyz="0.0 0.0 0.0" rpy="0.0 0.0 0.0" />
  </joint>

  <!-- Table -->
  <link name="table_link" type="fixed">
    <visual>
      <origin rpy="0 0 0" xyz="0 0 0"/>
      <geometry>
        <mesh filename="package://description/app/models/Table/Table.stl"/>
      </geometry>
      <material name="visual_app_mesh"/>
    </visual>
    <collision>
      <origin rpy="0 0 0" xyz="0 0 0"/>
      <geometry>
        <mesh filename="package://description/app/collision/Collision-Table.stl"/>
      </geometry>
    </collision>
  </link>
  <joint name="app_table_joint" type="fixed">
    <parent link="app" />
    <child link="table_link" />
    <origin xyz="0.0 0.36 -0.37" rpy="0.0 0.0 0.0" />
  </joint>

  <!-- 3D Printer -->
  <link name="3d_printer_link" type="fixed">
    <visual>
      <origin rpy="0 0 0" xyz="0 0 0"/>
      <geometry>
        <mesh filename="package://description/app/models/MK2-Printer/MK2-Printer.stl"/>
      </geometry>
      <material name="visual_app_mesh"/>
    </visual>
    <collision>
      <origin rpy="0 0 0" xyz="0 0 0"/>
      <geometry>
        <mesh filename="package://description/app/collision/Collision-MK2-Printer.stl"/>
      </geometry>
    </collision>
  </link>
  <joint name="app_3d_printer_joint" type="fixed">
    <parent link="app" />
    <child link="3d_printer_link" />
    <origin xyz="-0.28 0.32 0.3" rpy="0.0 0.0 0.0" />
  </joint>

  <!-- Product Box -->
  <link name="box_link" type="fixed">
    <visual>
      <origin rpy="0 0 0" xyz="0 0 0"/>
      <geometry>
        <mesh filename="package://description/app/models/Box/Box.stl"/>
      </geometry>
      <material name="visual_app_mesh"/>
    </visual>
    <collision>
      <origin rpy="0 0 0" xyz="0 0 0"/>
      <geometry>
        <mesh filename="package://description/app/collision/Collision-Box.stl"/>
      </geometry>
    </collision>
  </link>
  <joint name="app_box_joint" type="fixed">
    <parent link="app" />
    <child link="box_link" />
    <origin xyz="0.35 0.35 0.07" rpy="0.0 0.0 0.0" />
  </joint>

  <!-- Robot Pedestal -->
  <link name="ur3e_pedestal_link" type="fixed" >
    <visual>
      <origin rpy="0 0 0" xyz="0 0 0"/>
      <geometry>
        <mesh filename="package://description/app/models/ur3e-Pedestal/Pedestal.stl"/>
      </geometry>
      <material name="visual_app_mesh"/>
    </visual>
    <collision>
      <origin rpy="0 0 0" xyz="0 0 0"/>
      <geometry>
        <mesh filename="package://description/app/collision/Collision-Pedestal.stl"/>
      </geometry>
    </collision>
  </link>
  <joint name="robot_common_ur3e_pedestal_joint" type="fixed">
    <parent link="simulated_base_link" />
    <child link="ur3e_pedestal_link" />
    <origin xyz="0.0 0.0 -0.38" rpy="0.0 0.0 0.0" />
  </joint>

  <joint name="world_baselink_joint" type="fixed">
    <parent link="world"/>
    <child link="simulated_base_link"/>
    <origin xyz="0.0 0.0 0.0" rpy="0.0 0.0 0.0" />
  </joint>

  <!-- measured from model -->
  <link name="simulated_base_link">
    <visual>
      <geometry>
        <mesh filename="package://description/meshes/visual/base.dae"/>
      </geometry>
    </visual>
    <collision>
      <geometry>
        <mesh filename="package://description/meshes/collision/base.stl"/>
      </geometry>
    </collision>
    <inertial>
      <mass value="2.0"/>
      <origin rpy="0 0 0" xyz="0.0 0.0 0.0"/>
      <inertia ixx="0.0030531654454" ixy="0.0" ixz="0.0" iyy="0.0030531654454" iyz="0.0" izz="0.005625"/>
    </inertial>
  </link>
  <joint name="simulated_shoulder_pan_joint" type="revolute">
    <parent link="simulated_base_link"/>
    <child link="simulated_shoulder_link"/>
    <origin rpy="0.0 0.0 0.0" xyz="0.0 0.0 0.152"/>
    <axis xyz="0 0 1"/>
    <limit effort="330.0" lower="-6.28318530718" upper="6.28318530718" velocity="3.14"/>
    <dynamics damping="0.0" friction="0.0"/>
  </joint>
  <link name="simulated_shoulder_link">
    <visual>
      <geometry>
        <mesh filename="package://description/meshes/visual/shoulder.dae"/>
      </geometry>
    </visual>
    <collision>
      <geometry>
        <mesh filename="package://description/meshes/collision/shoulder.stl"/>
      </geometry>
    </collision>
    <inertial>
      <mass value="2.0"/>
      <origin rpy="0 0 0" xyz="0.0 0.0 0.0"/>
      <inertia ixx="0.0080931634294" ixy="0.0" ixz="0.0" iyy="0.0080931634294" iyz="0.0" izz="0.005625"/>
    </inertial>
  </link>
  <joint name="simulated_shoulder_lift_joint" type="revolute">
    <parent link="simulated_shoulder_link"/>
    <child link="simulated_upper_arm_link"/>
    <origin rpy="0.0 1.57079632679 0.0" xyz="0.0 0.12 0.0"/>
    <axis xyz="0 1 0"/>
    <limit effort="330.0" lower="-6.28318530718" upper="6.28318530718" velocity="3.14"/>
    <dynamics damping="0.0" friction="0.0"/>
  </joint>
  <link name="simulated_upper_arm_link">
    <visual>
      <geometry>
        <mesh filename="package://description/meshes/visual/upperarm.dae"/>
      </geometry>
    </visual>
    <collision>
      <geometry>
        <mesh filename="package://description/meshes/collision/upperarm.stl"/>
      </geometry>
    </collision>
    <inertial>
      <mass value="3.42"/>
      <origin rpy="0 0 0" xyz="0.0 0.0 0.122"/>
      <inertia ixx="0.0217771262891" ixy="0.0" ixz="0.0" iyy="0.0217771262891" iyz="0.0" izz="0.00961875"/>
    </inertial>
  </link>
  <joint name="simulated_elbow_joint" type="revolute">
    <parent link="simulated_upper_arm_link"/>
    <child link="simulated_forearm_link"/>
    <origin rpy="0.0 0.0 0.0" xyz="0.0 -0.093 0.244"/>
    <axis xyz="0 1 0"/>
    <limit effort="150.0" lower="-3.14159265359" upper="3.14159265359" velocity="3.14"/>
    <dynamics damping="0.0" friction="0.0"/>
  </joint>
  <link name="simulated_forearm_link">
    <visual>
      <geometry>
        <mesh filename="package://description/meshes/visual/forearm.dae"/>
      </geometry>
    </visual>
    <collision>
      <geometry>
        <mesh filename="package://description/meshes/collision/forearm.stl"/>
      </geometry>
    </collision>
    <inertial>
      <mass value="1.26"/>
      <origin rpy="0 0 0" xyz="0.0 0.0 0.1065"/>
      <inertia ixx="0.00653561738575" ixy="0.0" ixz="0.0" iyy="0.00653561738575" iyz="0.0" izz="0.00354375"/>
    </inertial>
  </link>
  <joint name="simulated_wrist_1_joint" type="revolute">
    <parent link="simulated_forearm_link"/>
    <child link="simulated_wrist_1_link"/>
    <origin rpy="0.0 1.57079632679 0.0" xyz="0.0 0.0 0.213"/>
    <axis xyz="0 1 0"/>
    <limit effort="54.0" lower="-6.28318530718" upper="6.28318530718" velocity="6.28"/>
    <dynamics damping="0.0" friction="0.0"/>
  </joint>
  <link name="simulated_wrist_1_link">
    <visual>
      <geometry>
        <mesh filename="package://description/meshes/visual/wrist1.dae"/>
      </geometry>
    </visual>
    <collision>
      <geometry>
        <mesh filename="package://description/meshes/collision/wrist1.stl"/>
      </geometry>
    </collision>
    <inertial>
      <mass value="0.8"/>
      <origin rpy="0 0 0" xyz="0.0 0.0 0.0"/>
      <inertia ixx="0.002084999166" ixy="0.0" ixz="0.0" iyy="0.002084999166" iyz="0.0" izz="0.00225"/>
    </inertial>
  </link>
  <joint name="simulated_wrist_2_joint" type="revolute">
    <parent link="simulated_wrist_1_link"/>
    <child link="simulated_wrist_2_link"/>
    <origin rpy="0.0 0.0 0.0" xyz="0.0 0.104 0.0"/>
    <axis xyz="0 0 1"/>
    <limit effort="54.0" lower="-6.28318530718" upper="6.28318530718" velocity="6.28"/>
    <dynamics damping="0.0" friction="0.0"/>
  </joint>
  <link name="simulated_wrist_2_link">
    <visual>
      <geometry>
        <mesh filename="package://description/meshes/visual/wrist2.dae"/>
      </geometry>
    </visual>
    <collision>
      <geometry>
        <mesh filename="package://description/meshes/collision/wrist2.stl"/>
      </geometry>
    </collision>
    <inertial>
      <mass value="0.8"/>
      <origin rpy="0 0 0" xyz="0.0 0.0 0.0"/>
      <inertia ixx="0.002084999166" ixy="0.0" ixz="0.0" iyy="0.002084999166" iyz="0.0" izz="0.00225"/>
    </inertial>
  </link>
  <joint name="simulated_wrist_3_joint" type="revolute">
    <parent link="simulated_wrist_2_link"/>
    <child link="simulated_wrist_3_link"/>
    <origin rpy="0.0 0.0 0.0" xyz="0.0 0.0 0.085"/>
    <axis xyz="0 1 0"/>
    <limit effort="54.0" lower="-6.28318530718" upper="6.28318530718" velocity="6.28"/>
    <dynamics damping="0.0" friction="0.0"/>
  </joint>
  <link name="simulated_wrist_3_link">
    <visual>
      <geometry>
        <mesh filename="package://description/meshes/visual/wrist3.dae"/>
      </geometry>
    </visual>
    <collision>
      <geometry>
        <mesh filename="package://description/meshes/collision/wrist3.stl"/>
      </geometry>
    </collision>
    <inertial>
      <mass value="0.35"/>
      <origin rpy="0 0 0" xyz="0.0 0.0 0.0"/>
      <inertia ixx="0.000912187135125" ixy="0.0" ixz="0.0" iyy="0.000912187135125" iyz="0.0" izz="0.000984375"/>
    </inertial>
  </link>
  <joint name="simulated_ee_fixed_joint" type="fixed">
    <parent link="simulated_wrist_3_link"/>
    <child link="simulated_ee_link"/>
    <origin rpy="0.0 0.0 1.57079632679" xyz="0.0 0.092 0.0"/>
  </joint>
  <link name="simulated_ee_link">
    <collision>
      <geometry>
        <box size="0.01 0.01 0.01"/>
      </geometry>
      <origin rpy="0 0 0" xyz="-0.01 0 0"/>
    </collision>
  </link>
  <transmission name="simulated_shoulder_pan_trans">
    <type>transmission_interface/SimpleTransmission</type>
    <joint name="simulated_shoulder_pan_joint">
      <hardwareInterface>hardware_interface/PositionJointInterface</hardwareInterface>
    </joint>
    <actuator name="simulated_shoulder_pan_motor">
      <mechanicalReduction>1</mechanicalReduction>
    </actuator>
  </transmission>
  <transmission name="simulated_shoulder_lift_trans">
    <type>transmission_interface/SimpleTransmission</type>
    <joint name="simulated_shoulder_lift_joint">
      <hardwareInterface>hardware_interface/PositionJointInterface</hardwareInterface>
    </joint>
    <actuator name="simulated_shoulder_lift_motor">
      <mechanicalReduction>1</mechanicalReduction>
    </actuator>
  </transmission>
  <transmission name="simulated_elbow_trans">
    <type>transmission_interface/SimpleTransmission</type>
    <joint name="simulated_elbow_joint">
      <hardwareInterface>hardware_interface/PositionJointInterface</hardwareInterface>
    </joint>
    <actuator name="simulated_elbow_motor">
      <mechanicalReduction>1</mechanicalReduction>
    </actuator>
  </transmission>
  <transmission name="simulated_wrist_1_trans">
    <type>transmission_interface/SimpleTransmission</type>
    <joint name="simulated_wrist_1_joint">
      <hardwareInterface>hardware_interface/PositionJointInterface</hardwareInterface>
    </joint>
    <actuator name="simulated_wrist_1_motor">
      <mechanicalReduction>1</mechanicalReduction>
    </actuator>
  </transmission>
  <transmission name="simulated_wrist_2_trans">
    <type>transmission_interface/SimpleTransmission</type>
    <joint name="simulated_wrist_2_joint">
      <hardwareInterface>hardware_interface/PositionJointInterface</hardwareInterface>
    </joint>
    <actuator name="simulated_wrist_2_motor">
      <mechanicalReduction>1</mechanicalReduction>
    </actuator>
  </transmission>
  <transmission name="simulated_wrist_3_trans">
    <type>transmission_interface/SimpleTransmission</type>
    <joint name="simulated_wrist_3_joint">
      <hardwareInterface>hardware_interface/PositionJointInterface</hardwareInterface>
    </joint>
    <actuator name="simulated_wrist_3_motor">
      <mechanicalReduction>1</mechanicalReduction>
    </actuator>
  </transmission>
  <gazebo reference="simulated_shoulder_link">
    <selfCollide>true</selfCollide>
  </gazebo>
  <gazebo reference="simulated_upper_arm_link">
    <selfCollide>true</selfCollide>
  </gazebo>
  <gazebo reference="simulated_forearm_link">
    <selfCollide>true</selfCollide>
  </gazebo>
  <gazebo reference="simulated_wrist_1_link">
    <selfCollide>true</selfCollide>
  </gazebo>
  <gazebo reference="simulated_wrist_3_link">
    <selfCollide>true</selfCollide>
  </gazebo>
  <gazebo reference="simulated_wrist_2_link">
    <selfCollide>true</selfCollide>
  </gazebo>
  <gazebo reference="simulated_ee_link">
    <selfCollide>true</selfCollide>
  </gazebo>
  <!-- ROS base_link to UR 'Base' Coordinates transform -->
  <link name="simulated_base"/>
  <joint name="simulated_base_link-base_fixed_joint" type="fixed">
    <!-- NOTE: this rotation is only needed as long as base_link itself is
                 not corrected wrt the real robot (ie: rotated over 180
                 degrees)
      -->
    <origin rpy="0 0 -3.14159265359" xyz="0 0 0"/>
    <parent link="simulated_base_link"/>
    <child link="simulated_base"/>
  </joint>
  <!-- Frame coincident with all-zeros TCP on UR controller -->
  <link name="simulated_tool0"/>
  <joint name="simulated_wrist_3_link-tool0_fixed_joint" type="fixed">
    <origin rpy="-1.57079632679 0 0" xyz="0 0.092 0"/>
    <parent link="simulated_wrist_3_link"/>
    <child link="simulated_tool0"/>
  </joint>

  <joint name="simulated_robotiq_85_base_joint" type="fixed">
    <parent link="simulated_tool0"/>
    <child link="simulated_robotiq_85_base_link"/>
    <origin rpy="1.570795 -1.570795 0" xyz="0 0 0"/>
  </joint>
  <link name="simulated_robotiq_85_base_link">
    <visual>
      <geometry>
        <mesh filename="package://description/meshes/visual/robotiq_85_base_link.dae"/>
      </geometry>
    </visual>
    <collision>
      <geometry>
        <mesh filename="package://description/meshes/collision/robotiq_85_base_link.stl"/>
      </geometry>
    </collision>
    <inertial>
      <mass value="0.636951"/>
      <origin xyz="0.0 0.0 0.0"/>
      <inertia ixx="0.000380" ixy="0.000000" ixz="0.000000" iyx="0.000000" iyy="0.001110" iyz="0.000000" izx="0.000000" izy="0.000000" izz="0.001171"/>
    </inertial>
  </link>
  <joint name="simulated_robotiq_85_left_knuckle_joint" type="revolute">
    <parent link="simulated_robotiq_85_base_link"/>
    <child link="simulated_robotiq_85_left_knuckle_link"/>
    <axis xyz="0 0 1"/>
    <origin rpy="3.14159 0.0 0.0" xyz="0.05490451627 0.03060114443 0.0"/>
    <limit effort="1000" lower="0.0" upper="0.804" velocity="2.0"/>
  </joint>
  <joint name="simulated_robotiq_85_right_knuckle_joint" type="continuous">
    <parent link="simulated_robotiq_85_base_link"/>
    <child link="simulated_robotiq_85_right_knuckle_link"/>
    <axis xyz="0 0 1"/>
    <origin rpy="0.0 0.0 0.0" xyz="0.05490451627 -0.03060114443 0.0"/>
    <limit effort="1000" lower="-3.14" upper="3.14" velocity="100.0"/>
    <mimic joint="robotiq_85_left_knuckle_joint"/>
  </joint>
  <link name="simulated_robotiq_85_left_knuckle_link">
    <visual>
      <geometry>
        <mesh filename="package://description/meshes/visual/robotiq_85_knuckle_link.dae"/>
      </geometry>
    </visual>
    <collision>
      <geometry>
        <mesh filename="package://description/meshes/collision/robotiq_85_knuckle_link.stl"/>
      </geometry>
    </collision>
    <inertial>
      <mass value="0.018491"/>
      <origin xyz="0.0 0.0 0.0"/>
      <inertia ixx="0.000009" ixy="-0.000001" ixz="0.000000" iyx="-0.000001" iyy="0.000001" iyz="0.000000" izx="0.000000" izy="0.000000" izz="0.000010"/>
    </inertial>
  </link>
  <link name="simulated_robotiq_85_right_knuckle_link">
    <visual>
      <geometry>
        <mesh filename="package://description/meshes/visual/robotiq_85_knuckle_link.dae"/>
      </geometry>
    </visual>
    <collision>
      <geometry>
        <mesh filename="package://description/meshes/collision/robotiq_85_knuckle_link.stl"/>
      </geometry>
    </collision>
    <inertial>
      <mass value="0.018491"/>
      <origin xyz="0.0 0.0 0.0"/>
      <inertia ixx="0.000009" ixy="-0.000001" ixz="0.000000" iyx="-0.000001" iyy="0.000001" iyz="0.000000" izx="0.000000" izy="0.000000" izz="0.000010"/>
    </inertial>
  </link>
  <joint name="simulated_robotiq_85_left_finger_joint" type="continuous">
    <parent link="simulated_robotiq_85_left_knuckle_link"/>
    <child link="simulated_robotiq_85_left_finger_link"/>
    <origin rpy="0 0 0" xyz="-0.00408552455 -0.03148604435 0.0"/>
  </joint>
  <joint name="simulated_robotiq_85_right_finger_joint" type="continuous">
    <parent link="simulated_robotiq_85_right_knuckle_link"/>
    <child link="simulated_robotiq_85_right_finger_link"/>
    <origin rpy="0 0 0" xyz="-0.00408552455 -0.03148604435 0.0"/>
  </joint>
  <link name="simulated_robotiq_85_left_finger_link">
    <visual>
      <geometry>
        <mesh filename="package://description/meshes/visual/robotiq_85_finger_link.dae"/>
      </geometry>
    </visual>
    <collision>
      <geometry>
        <mesh filename="package://description/meshes/collision/robotiq_85_finger_link.stl"/>
      </geometry>
    </collision>
    <inertial>
      <mass value="0.027309"/>
      <origin xyz="0.0 0.0 0.0"/>
      <inertia ixx="0.000003" ixy="-0.000002" ixz="0.000000" iyx="-0.000002" iyy="0.000021" iyz="0.000000" izx="0.000000" izy="0.000000" izz="0.000020"/>
    </inertial>
  </link>
  <link name="simulated_robotiq_85_right_finger_link">
    <visual>
      <geometry>
        <mesh filename="package://description/meshes/visual/robotiq_85_finger_link.dae"/>
      </geometry>
    </visual>
    <collision>
      <geometry>
        <mesh filename="package://description/meshes/collision/robotiq_85_finger_link.stl"/>
      </geometry>
    </collision>
    <inertial>
      <mass value="0.027309"/>
      <origin xyz="0.0 0.0 0.0"/>
      <inertia ixx="0.000003" ixy="-0.000002" ixz="0.000000" iyx="-0.000002" iyy="0.000021" iyz="0.000000" izx="0.000000" izy="0.000000" izz="0.000020"/>
    </inertial>
  </link>
  <joint name="simulated_robotiq_85_left_inner_knuckle_joint" type="continuous">
    <parent link="simulated_robotiq_85_base_link"/>
    <child link="simulated_robotiq_85_left_inner_knuckle_link"/>
    <axis xyz="0 0 1"/>
    <origin rpy="3.14159 0.0 0.0" xyz="0.06142 0.0127 0"/>
    <limit effort="0.1" lower="-3.14" upper="3.14" velocity="100.0"/>
    <mimic joint="robotiq_85_left_knuckle_joint" offset="0"/>
  </joint>
  <joint name="simulated_robotiq_85_right_inner_knuckle_joint" type="continuous">
    <parent link="simulated_robotiq_85_base_link"/>
    <child link="simulated_robotiq_85_right_inner_knuckle_link"/>
    <axis xyz="0 0 1"/>
    <origin rpy="0 0 0" xyz="0.06142 -0.0127 0"/>
    <limit effort="0.1" lower="-3.14" upper="3.14" velocity="100.0"/>
    <mimic joint="robotiq_85_left_knuckle_joint" offset="0"/>
  </joint>
  <link name="simulated_robotiq_85_left_inner_knuckle_link">
    <visual>
      <geometry>
        <mesh filename="package://description/meshes/visual/robotiq_85_inner_knuckle_link.dae"/>
      </geometry>
    </visual>
    <collision>
      <geometry>
        <mesh filename="package://description/meshes/collision/robotiq_85_inner_knuckle_link.stl"/>
      </geometry>
    </collision>
    <inertial>
      <mass value="0.029951"/>
      <origin xyz="0.0 0.0 0.0"/>
      <inertia ixx="0.000039" ixy="0.000000" ixz="0.000000" iyx="0.000000" iyy="0.000005" iyz="0.000000" izx="0.000000" izy="0.000000" izz="0.000035"/>
    </inertial>
  </link>
  <link name="simulated_robotiq_85_right_inner_knuckle_link">
    <visual>
      <geometry>
        <mesh filename="package://description/meshes/visual/robotiq_85_inner_knuckle_link.dae"/>
      </geometry>
    </visual>
    <collision>
      <geometry>
        <mesh filename="package://description/meshes/collision/robotiq_85_inner_knuckle_link.stl"/>
      </geometry>
    </collision>
    <inertial>
      <mass value="0.029951"/>
      <origin xyz="0.0 0.0 0.0"/>
      <inertia ixx="0.000039" ixy="0.000000" ixz="0.000000" iyx="0.000000" iyy="0.000005" iyz="0.000000" izx="0.000000" izy="0.000000" izz="0.000035"/>
    </inertial>
  </link>
  <joint name="simulated_robotiq_85_left_finger_tip_joint" type="continuous">
    <parent link="simulated_robotiq_85_left_inner_knuckle_link"/>
    <child link="simulated_robotiq_85_left_finger_tip_link"/>
    <axis xyz="0 0 1"/>
    <origin rpy="0.0 0.0 0.0" xyz="0.04303959807 -0.03759940821 0.0"/>
    <limit effort="0.1" lower="-3.14" upper="3.14" velocity="100.0"/>
    <mimic joint="robotiq_85_left_knuckle_joint" multiplier="-1"/>
  </joint>
  <joint name="simulated_robotiq_85_right_finger_tip_joint" type="continuous">
    <parent link="simulated_robotiq_85_right_inner_knuckle_link"/>
    <child link="simulated_robotiq_85_right_finger_tip_link"/>
    <axis xyz="0 0 1"/>
    <origin rpy="0.0 0.0 0.0" xyz="0.04303959807 -0.03759940821  0.0"/>
    <limit effort="0.1" lower="-3.14" upper="3.14" velocity="100.0"/>
    <mimic joint="robotiq_85_left_knuckle_joint" multiplier="-1"/>
  </joint>
  <link name="simulated_robotiq_85_left_finger_tip_link">
    <visual>
      <geometry>
        <mesh filename="package://description/meshes/visual/robotiq_85_finger_tip_link.dae"/>
      </geometry>
    </visual>
    <collision>
      <geometry>
        <mesh filename="package://description/meshes/collision/robotiq_85_finger_tip_link.stl"/>
      </geometry>
    </collision>
    <inertial>
      <mass value="0.019555"/>
      <origin xyz="0.0 0.0 0.0"/>
      <inertia ixx="0.000002" ixy="0.000000" ixz="0.000000" iyx="0.000000" iyy="0.000005" iyz="0.000000" izx="0.000000" izy="0.000000" izz="0.000006"/>
    </inertial>
  </link>
  <link name="simulated_robotiq_85_right_finger_tip_link">
    <visual>
      <geometry>
        <mesh filename="package://description/meshes/visual/robotiq_85_finger_tip_link.dae"/>
      </geometry>
    </visual>
    <collision>
      <geometry>
        <mesh filename="package://description/meshes/collision/robotiq_85_finger_tip_link.stl"/>
      </geometry>
    </collision>
    <inertial>
      <mass value="0.019555"/>
      <origin xyz="0.0 0.0 0.0"/>
      <inertia ixx="0.000002" ixy="0.000000" ixz="0.000000" iyx="0.000000" iyy="0.000005" iyz="0.000000" izx="0.000000" izy="0.000000" izz="0.000006"/>
    </inertial>
  </link>
  <transmission name="simulated_robotiq_85_left_knuckle_trans">
    <type>transmission_interface/SimpleTransmission</type>
    <joint name="simulated_robotiq_85_left_knuckle_joint">
      <hardwareInterface>PositionJointInterface</hardwareInterface>
    </joint>
    <actuator name="simulated_robotiq_85_left_knuckle_motor">
      <mechanicalReduction>1</mechanicalReduction>
      <hardwareInterface>PositionJointInterface</hardwareInterface>
    </actuator>
  </transmission>
  <gazebo>
    <!-- loading plugin: mimic joints works in gazebo now -->
    <plugin filename="libroboticsgroup_gazebo_mimic_joint_plugin.so" name="simulated_mimic_robotiq_85_1">
      <joint>robotiq_85_left_knuckle_joint</joint>
      <mimicJoint>robotiq_85_right_knuckle_joint</mimicJoint>
      <!--multiplier>1.0</multiplier>
                <offset>0.0</offset-->
    </plugin>
    <plugin filename="libroboticsgroup_gazebo_mimic_joint_plugin.so" name="simulated_mimic_robotiq_85_2">
      <joint>robotiq_85_left_knuckle_joint</joint>
      <mimicJoint>robotiq_85_left_inner_knuckle_joint</mimicJoint>
      <!--multiplier>1.0</multiplier>
                <offset>0.0</offset-->
    </plugin>
    <plugin filename="libroboticsgroup_gazebo_mimic_joint_plugin.so" name="simulated_mimic_robotiq_85_3">
      <joint>robotiq_85_left_knuckle_joint</joint>
      <mimicJoint>robotiq_85_right_inner_knuckle_joint</mimicJoint>
      <!--multiplier>1.0</multiplier>
                <offset>0.0</offset-->
    </plugin>
    <plugin filename="libroboticsgroup_gazebo_mimic_joint_plugin.so" name="simulated_mimic_robotiq_85_4">
      <joint>robotiq_85_left_knuckle_joint</joint>
      <mimicJoint>robotiq_85_left_finger_tip_joint</mimicJoint>
      <!--multiplier>-1.0</multiplier-->
      <!--offset>0.0</offset-->
    </plugin>
    <plugin filename="libroboticsgroup_gazebo_mimic_joint_plugin.so" name="simulated_mimic_robotiq_85_5">
      <joint>robotiq_85_left_knuckle_joint</joint>
      <mimicJoint>robotiq_85_right_finger_tip_joint</mimicJoint>
      <!--multiplier>-1.0</multiplier-->
      <!--offset>0.0</offset-->
    </plugin>
  </gazebo>
</robot>
